Workbook
Name Categoria: 'Validación'!$A$2:$A$10
Name Tipo: 'Validación'!$B$2:$B$4
Name Subcategoria: 'Validación'!$C$2:$C$28

Sheet Global Precios
A1: ID | B1: Codigo de barras | C1: Tipo | D1: Producto | E1: Marca | F1: Categoría | G1: Subcategoría | H1: Costo unitario s/iva | I1: Descuento | J1: Costo c/Iva | K1: Margen | L1: Precio al publico c/iva | M1: Presentación | N1: Unidad | O1: KG al publico | P1: Ultima Actualización | Q1: Longitud | R1: Frec. de actu | T1: Limpio de lista | U1: Dividir por: | V1: Costo c/iva a pasar: | W1: % de aumento | X1: Foto Producto | Y1: Stock | Z1: Uso | AA1: Codigo proveedor
A2: 1 | C2: Servicio | D2: Castración Gata | E2: Arlekyn | F2: Clinica | H2: =IF(J2="","",J2/1.21) -> 68163.636 | J2: 82478 | L2: =IF('Global Precios'!J2*(1-I2)*(1+'Global Precios'!K2)>10000,MROUND('Global Precios'!J2*(1-I2)*(1+'Global Precios'!K2),1000),MROUND('Global Precios'!J2*(1-I2)*(1+'Global Precios'!K2),500)) -> 82000 | M2: 1 | N2: c/u | P2: 45809 | Q2: =LEN(D2) -> 15 | R2: 60 | T2: =IFERROR(VLOOKUP(D2,BUSCARV!$A$1:$C$5524,2,0),"") | V2: =IF(U2="",T2,T2/U2) | W2: =IF(V2="","", IFERROR((V2-J2)/J2,"")) | Y2: =IFERROR(VLOOKUP(A2,#REF!,3,0),0) -> 0 | Z2: Activo
A3: 2 | C3: Servicio | D3: Castración perra hasta 10 kg | E3: Arlekyn | F3: Clinica | H3: =IF(J3="","",J3/1.21) -> 83251.24 | J3: 100734 | L3: =IF('Global Precios'!J3*(1-I3)*(1+'Global Precios'!K3)>10000,MROUND('Global Precios'!J3*(1-I3)*(1+'Global Precios'!K3),1000),MROUND('Global Precios'!J3*(1-I3)*(1+'Global Precios'!K3),500)) -> 101000 | M3: 1 | N3: c/u | P3: 45809 | Q3: =LEN(D3) -> 28 | R3: 60 | T3: =IFERROR(VLOOKUP(D3,BUSCARV!$A$1:$C$5524,2,0),"") | V3: =IF(U3="",T3,T3/U3) | W3: =IF(V3="","", IFERROR((V3-J3)/J3,"")) | Y3: =IFERROR(VLOOKUP(A3,#REF!,3,0),0) -> 0 | Z3: Activo
A4: 3 | C4: Servicio | D4: Castración perra hasta 20 kg | E4: Arlekyn | F4: Clinica | H4: =IF(J4="","",J4/1.21) -> 85819.835 | J4: 103842 | L4: =IF('Global Precios'!J4*(1-I4)*(1+'Global Precios'!K4)>10000,MROUND('Global Precios'!J4*(1-I4)*(1+'Global Precios'!K4),1000),MROUND('Global Precios'!J4*(1-I4)*(1+'Global Precios'!K4),500)) -> 104000 | M4: 1 | N4: c/u | P4: 45809 | Q4: =LEN(D4) -> 28 | R4: 60 | T4: =IFERROR(VLOOKUP(D4,BUSCARV!$A$1:$C$5524,2,0),"") | V4: =IF(U4="",T4,T4/U4) | W4: =IF(V4="","", IFERROR((V4-J4)/J4,"")) | Y4: =IFERROR(VLOOKUP(A4,#REF!,3,0),0) -> 0 | Z4: Activo
A5: 4 | C5: Servicio | D5: Castración perra hasta 30 kg | E5: Arlekyn | F5: Clinica | H5: =IF(J5="","",J5/1.21) -> 90454.545 | J5: 109450 | L5: =IF('Global Precios'!J5*(1-I5)*(1+'Global Precios'!K5)>10000,MROUND('Global Precios'!J5*(1-I5)*(1+'Global Precios'!K5),1000),MROUND('Global Precios'!J5*(1-I5)*(1+'Global Precios'!K5),500)) -> 109000 | M5: 1 | N5: c/u | P5: 45809 | Q5: =LEN(D5) -> 28 | R5: 60 | T5: =IFERROR(VLOOKUP(D5,BUSCARV!$A$1:$C$5524,2,0),"") | V5: =IF(U5="",T5,T5/U5) | W5: =IF(V5="","", IFERROR((V5-J5)/J5,"")) | Y5: =IFERROR(VLOOKUP(A5,#REF!,3,0),0) -> 0 | Z5: Activo
A6: 5 | C6: Servicio | D6: Castración perra hasta 40 kg | E6: Arlekyn | F6: Clinica | H6: =IF(J6="","",J6/1.21) -> 97890.083 | J6: 118447 | L6: =IF('Global Precios'!J6*(1-I6)*(1+'Global Precios'!K6)>10000,MROUND('Global Precios'!J6*(1-I6)*(1+'Global Precios'!K6),1000),MROUND('Global Precios'!J6*(1-I6)*(1+'Global Precios'!K6),500)) -> 118000 | M6: 1 | N6: c/u | P6: 45809 | Q6: =LEN(D6) -> 28 | R6: 60 | T6: =IFERROR(VLOOKUP(D6,BUSCARV!$A$1:$C$5524,2,0),"") | V6: =IF(U6="",T6,T6/U6) | W6: =IF(V6="","", IFERROR((V6-J6)/J6,"")) | Y6: =IFERROR(VLOOKUP(A6,#REF!,3,0),0) -> 0 | Z6: Activo
A7: 6 | C7: Servicio | D7: Castración perra hasta 50 kg | E7: Arlekyn | F7: Clinica | H7: =IF(J7="","",J7/1.21) -> 105325.62 | J7: 127444 | L7: =IF('Global Precios'!J7*(1-I7)*(1+'Global Precios'!K7)>10000,MROUND('Global Precios'!J7*(1-I7)*(1+'Global Precios'!K7),1000),MROUND('Global Precios'!J7*(1-I7)*(1+'Global Precios'!K7),500)) -> 127000 | M7: 1 | N7: c/u | P7: 45809 | Q7: =LEN(D7) -> 28 | R7: 60 | T7: =IFERROR(VLOOKUP(D7,BUSCARV!$A$1:$C$5524,2,0),"") | V7: =IF(U7="",T7,T7/U7) | W7: =IF(V7="","", IFERROR((V7-J7)/J7,"")) | Y7: =IFERROR(VLOOKUP(A7,#REF!,3,0),0) -> 0 | Z7: Activo
A8: 7 | C8: Servicio | D8: Castración perra hasta 60 kg | E8: Arlekyn | F8: Clinica | H8: =IF(J8="","",J8/1.21) -> 114000.83 | J8: 137941 | L8: =IF('Global Precios'!J8*(1-I8)*(1+'Global Precios'!K8)>10000,MROUND('Global Precios'!J8*(1-I8)*(1+'Global Precios'!K8),1000),MROUND('Global Precios'!J8*(1-I8)*(1+'Global Precios'!K8),500)) -> 138000 | M8: 1 | N8: c/u | P8: 45809 | Q8: =LEN(D8) -> 28 | R8: 60 | T8: =IFERROR(VLOOKUP(D8,BUSCARV!$A$1:$C$5524,2,0),"") | V8: =IF(U8="",T8,T8/U8) | W8: =IF(V8="","", IFERROR((V8-J8)/J8,"")) | Y8: =IFERROR(VLOOKUP(A8,#REF!,3,0),0) -> 0 | Z8: Activo
A9: 8 | C9: Servicio | D9: Corte de colitas camadas hasta 3 cachorros | E9: Arlekyn | F9: Clinica | H9: =IF(J9="","",J9/1.21) -> 14871.074 | J9: 17994 | L9: =IF('Global Precios'!J9*(1-I9)*(1+'Global Precios'!K9)>1000,MROUND('Global Precios'!J9*(1-I9)*(1+'Global Precios'!K9),100),MROUND('Global Precios'!J9*(1-I9)*(1+'Global Precios'!K9),10)) -> 18000 | M9: 1 | N9: c/u | P9: 45809 | Q9: =LEN(D9) -> 42 | R9: 60 | T9: =IFERROR(VLOOKUP(D9,BUSCARV!$A$1:$C$5524,2,0),"") | V9: =IF(U9="",T9,T9/U9) | W9: =IF(V9="","", IFERROR((V9-J9)/J9,"")) | Y9: =IFERROR(VLOOKUP(A9,#REF!,3,0),0) -> 0 | Z9: Desactivado
A10: 9 | C10: Servicio | D10: Corte de colitas camadas hasta 4 cachorros | E10: Arlekyn | F10: Clinica | H10: =IF(J10="","",J10/1.21) -> 12143.802 | J10: 14694 | L10: =IF('Global Precios'!J10*(1-I10)*(1+'Global Precios'!K10)>1000,MROUND('Global Precios'!J10*(1-I10)*(1+'Global Precios'!K10),100),MROUND('Global Precios'!J10*(1-I10)*(1+'Global Precios'!K10),10)) -> 14700 | M10: 1 | N10: c/u | P10: 45809 | Q10: =LEN(D10) -> 42 | R10: 60 | T10: =IFERROR(VLOOKUP(D10,BUSCARV!$A$1:$C$5524,2,0),"") | V10: =IF(U10="",T10,T10/U10) | W10: =IF(V10="","", IFERROR((V10-J10)/J10,"")) | Y10: =IFERROR(VLOOKUP(A10,#REF!,3,0),0) -> 0 | Z10: Desactivado
A11: 10 | C11: Servicio | D11: Eutanasia hasta 10 kg | E11: Arlekyn | F11: Clinica | H11: =IF(J11="","",J11/1.21) -> 50544.628 | J11: 61159 | L11: =IF('Global Precios'!J11*(1-I11)*(1+'Global Precios'!K11)>10000,MROUND('Global Precios'!J11*(1-I11)*(1+'Global Precios'!K11),1000),MROUND('Global Precios'!J11*(1-I11)*(1+'Global Precios'!K11),500)) -> 61000 | M11: 1 | N11: c/u | P11: 45809 | Q11: =LEN(D11) -> 21 | R11: 60 | T11: =IFERROR(VLOOKUP(D11,BUSCARV!$A$1:$C$5524,2,0),"") | V11: =IF(U11="",T11,T11/U11) | W11: =IF(V11="","", IFERROR((V11-J11)/J11,"")) | Y11: =IFERROR(VLOOKUP(A11,#REF!,3,0),0) -> 0 | Z11: Activo
A12: 11 | C12: Servicio | D12: Eutanasia hasta 20 kg | E12: Arlekyn | F12: Clinica | H12: =IF(J12="","",J12/1.21) -> 60022.314 | J12: 72627 | L12: =IF('Global Precios'!J12*(1-I12)*(1+'Global Precios'!K12)>10000,MROUND('Global Precios'!J12*(1-I12)*(1+'Global Precios'!K12),1000),MROUND('Global Precios'!J12*(1-I12)*(1+'Global Precios'!K12),500)) -> 73000 | M12: 1 | N12: c/u | P12: 45809 | Q12: =LEN(D12) -> 21 | R12: 60 | T12: =IFERROR(VLOOKUP(D12,BUSCARV!$A$1:$C$5524,2,0),"") | V12: =IF(U12="",T12,T12/U12) | W12: =IF(V12="","", IFERROR((V12-J12)/J12,"")) | Y12: =IFERROR(VLOOKUP(A12,#REF!,3,0),0) -> 0 | Z12: Activo
A13: 12 | C13: Servicio | D13: Eutanasia hasta 30 kg | E13: Arlekyn | F13: Clinica | H13: =IF(J13="","",J13/1.21) -> 71605.785 | J13: 86643 | L13: =IF('Global Precios'!J13*(1-I13)*(1+'Global Precios'!K13)>10000,MROUND('Global Precios'!J13*(1-I13)*(1+'Global Precios'!K13),1000),MROUND('Global Precios'!J13*(1-I13)*(1+'Global Precios'!K13),500)) -> 87000 | M13: 1 | N13: c/u | P13: 45809 | Q13: =LEN(D13) -> 21 | R13: 60 | T13: =IFERROR(VLOOKUP(D13,BUSCARV!$A$1:$C$5524,2,0),"") | V13: =IF(U13="",T13,T13/U13) | W13: =IF(V13="","", IFERROR((V13-J13)/J13,"")) | Y13: =IFERROR(VLOOKUP(A13,#REF!,3,0),0) -> 0 | Z13: Activo
A14: 13 | C14: Servicio | D14: Eutanasia hasta 40 kg | E14: Arlekyn | F14: Clinica | H14: =IF(J14="","",J14/1.21) -> 82136.364 | J14: 99385 | L14: =IF('Global Precios'!J14*(1-I14)*(1+'Global Precios'!K14)>10000,MROUND('Global Precios'!J14*(1-I14)*(1+'Global Precios'!K14),1000),MROUND('Global Precios'!J14*(1-I14)*(1+'Global Precios'!K14),500)) -> 99000 | M14: 1 | N14: c/u | P14: 45809 | Q14: =LEN(D14) -> 21 | R14: 60 | T14: =IFERROR(VLOOKUP(D14,BUSCARV!$A$1:$C$5524,2,0),"") | V14: =IF(U14="",T14,T14/U14) | W14: =IF(V14="","", IFERROR((V14-J14)/J14,"")) | Y14: =IFERROR(VLOOKUP(A14,#REF!,3,0),0) -> 0 | Z14: Activo
A15: 14 | C15: Servicio | D15: Eutanasia hasta 50 kg | E15: Arlekyn | F15: Clinica | H15: =IF(J15="","",J15/1.21) -> 90454.545 | J15: 109450 | L15: =IF('Global Precios'!J15*(1-I15)*(1+'Global Precios'!K15)>10000,MROUND('Global Precios'!J15*(1-I15)*(1+'Global Precios'!K15),1000),MROUND('Global Precios'!J15*(1-I15)*(1+'Global Precios'!K15),500)) -> 109000 | M15: 1 | N15: c/u | P15: 45809 | Q15: =LEN(D15) -> 21 | R15: 60 | T15: =IFERROR(VLOOKUP(D15,BUSCARV!$A$1:$C$5524,2,0),"") | V15: =IF(U15="",T15,T15/U15) | W15: =IF(V15="","", IFERROR((V15-J15)/J15,"")) | Y15: =IFERROR(VLOOKUP(A15,#REF!,3,0),0) -> 0 | Z15: Activo
A16: 15 | C16: Servicio | D16: consulta + Internación medio día PROMEDIO | E16: Arlekyn | F16: Clinica | H16: =IF(J16="","",J16/1.21) -> 29740.496 | J16: 35986 | L16: =IF('Global Precios'!J16*(1-I16)*(1+'Global Precios'!K16)>10000,MROUND('Global Precios'!J16*(1-I16)*(1+'Global Precios'!K16),1000),MROUND('Global Precios'!J16*(1-I16)*(1+'Global Precios'!K16),500)) -> 36000 | M16: 1 | N16: c/u | P16: 45809 | Q16: =LEN(D16) -> 41 | R16: 60 | T16: =IFERROR(VLOOKUP(D16,BUSCARV!$A$1:$C$5524,2,0),"") | V16: =IF(U16="",T16,T16/U16) | W16: =IF(V16="","", IFERROR((V16-J16)/J16,"")) | Y16: =IFERROR(VLOOKUP(A16,#REF!,3,0),0) -> 0 | Z16: Desactivado
A17: 16 | C17: Servicio | D17: Medio día sin consulta PROMEDIO | E17: Arlekyn | F17: Clinica | H17: =IF(J17="","",J17/1.21) -> 18587.603 | J17: 22491 | L17: =IF('Global Precios'!J17*(1-I17)*(1+'Global Precios'!K17)>10000,MROUND('Global Precios'!J17*(1-I17)*(1+'Global Precios'!K17),1000),MROUND('Global Precios'!J17*(1-I17)*(1+'Global Precios'!K17),500)) -> 22000 | M17: 1 | N17: c/u | P17: 45809 | Q17: =LEN(D17) -> 31 | R17: 60 | T17: =IFERROR(VLOOKUP(D17,BUSCARV!$A$1:$C$5524,2,0),"") | V17: =IF(U17="",T17,T17/U17) | W17: =IF(V17="","", IFERROR((V17-J17)/J17,"")) | Y17: =IFERROR(VLOOKUP(A17,#REF!,3,0),0) -> 0 | Z17: Activo
A18: 17 | C18: Servicio | D18: Consulta + día completo PROMEDIO | E18: Arlekyn | F18: Clinica | H18: =IF(J18="","",J18/1.21) -> 40890.083 | J18: 49477 | L18: =IF('Global Precios'!J18*(1-I18)*(1+'Global Precios'!K18)>10000,MROUND('Global Precios'!J18*(1-I18)*(1+'Global Precios'!K18),1000),MROUND('Global Precios'!J18*(1-I18)*(1+'Global Precios'!K18),500)) -> 49000 | M18: 1 | N18: c/u | P18: 45809 | Q18: =LEN(D18) -> 32 | R18: 60 | T18: =IFERROR(VLOOKUP(D18,BUSCARV!$A$1:$C$5524,2,0),"") | V18: =IF(U18="",T18,T18/U18) | W18: =IF(V18="","", IFERROR((V18-J18)/J18,"")) | Y18: =IFERROR(VLOOKUP(A18,#REF!,3,0),0) -> 0 | Z18: Activo
A19: 18 | C19: Servicio | D19: Día completo sin consulta PROMEDIO | E19: Arlekyn | F19: Clinica | H19: =IF(J19="","",J19/1.21) -> 32214.876 | J19: 38980 | L19: =IF('Global Precios'!J19*(1-I19)*(1+'Global Precios'!K19)>10000,MROUND('Global Precios'!J19*(1-I19)*(1+'Global Precios'!K19),1000),MROUND('Global Precios'!J19*(1-I19)*(1+'Global Precios'!K19),500)) -> 39000 | M19: 1 | N19: c/u | P19: 45809 | Q19: =LEN(D19) -> 34 | R19: 60 | T19: =IFERROR(VLOOKUP(D19,BUSCARV!$A$1:$C$5524,2,0),"") | V19: =IF(U19="",T19,T19/U19) | W19: =IF(V19="","", IFERROR((V19-J19)/J19,"")) | Y19: =IFERROR(VLOOKUP(A19,#REF!,3,0),0) -> 0 | Z19: Activo
A20: 19 | C20: Servicio | D20: Corte de uñas | E20: Arlekyn | F20: Clinica | H20: =IF(J20="","",J20/1.21) -> 5003.3058 | J20: 6054 | L20: =IF('Global Precios'!J20*(1-I20)*(1+'Global Precios'!K20)>10000,MROUND('Global Precios'!J20*(1-I20)*(1+'Global Precios'!K20),1000),MROUND('Global Precios'!J20*(1-I20)*(1+'Global Precios'!K20),500)) -> 6000 | M20: 1 | N20: c/u | P20: 45809 | Q20: =LEN(D20) -> 13 | R20: 60 | T20: =IFERROR(VLOOKUP(D20,BUSCARV!$A$1:$C$5524,2,0),"") | V20: =IF(U20="",T20,T20/U20) | W20: =IF(V20="","", IFERROR((V20-J20)/J20,"")) | Y20: =IFERROR(VLOOKUP(A20,#REF!,3,0),0) -> 0 | Z20: Activo
A21: 20 | C21: Servicio | D21: Consulta clinica | E21: Arlekyn | F21: Clinica | H21: =IF(J21="","",J21/1.21) -> 12143.802 | J21: 14694 | L21: =IF('Global Precios'!J21*(1-I21)*(1+'Global Precios'!K21)>10000,MROUND('Global Precios'!J21*(1-I21)*(1+'Global Precios'!K21),1000),MROUND('Global Precios'!J21*(1-I21)*(1+'Global Precios'!K21),500)) -> 15000 | M21: 1 | N21: c/u | P21: 45809 | Q21: =LEN(D21) -> 16 | R21: 60 | T21: =IFERROR(VLOOKUP(D21,BUSCARV!$A$1:$C$5524,2,0),"") | V21: =IF(U21="",T21,T21/U21) | W21: =IF(V21="","", IFERROR((V21-J21)/J21,"")) | Y21: =IFERROR(VLOOKUP(A21,#REF!,3,0),0) -> 0 | Z21: Activo
A22: 21 | B22: 12393470 | C22: Producto | D22: EXCELLENT PUPPY(r.medianas y grandes) Present:15kg | E22: Excellent | F22: Alimentos | G22: Perro | H22: =IF(J22="","",J22/1.21) -> 49917.355 | I22: 0.065 | J22: 60400 | K22: 0.33 | L22: =IF('Global Precios'!J22*(1-I22)*(1+'Global Precios'!K22)>10000,MROUND('Global Precios'!J22*(1-I22)*(1+'Global Precios'!K22),1000),MROUND('Global Precios'!J22*(1-I22)*(1+'Global Precios'!K22),500)) -> 75000 | M22: 15 | N22: kg | O22: =+MROUND(('Global Precios'!$J22/('Global Precios'!$M22))*(1+'Global Precios'!$K22+0.1),10) -> 5760 | P22: 46174 | Q22: =LEN(D22) -> 50 | R22: 30 | T22: =IFERROR(VLOOKUP(D22,BUSCARV!$A$1:$C$5524,2,0),"") | V22: =IF(U22="",T22,T22/U22) | W22: =IF(V22="","", IFERROR((V22-J22)/J22,"")) | Y22: =IFERROR(VLOOKUP(A22,#REF!,3,0),0) -> 0 | Z22: Desactivado
A23: 22 | B23: 12393468 | C23: Producto | D23: EXCELLENT ADULT.(r. medianas y grandes) Pres:15kg | E23: Excellent | F23: Alimentos | G23: Perro | H23: =IF(J23="","",J23/1.21) -> 17839.669 | I23: 0.065 | J23: 21586 | K23: 0.33 | L23: =IF('Global Precios'!J23*(1-I23)*(1+'Global Precios'!K23)>1000,MROUND('Global Precios'!J23*(1-I23)*(1+'Global Precios'!K23),100),MROUND('Global Precios'!J23*(1-I23)*(1+'Global Precios'!K23),10)) -> 26800 | M23: 15 | N23: kg | O23: =+MROUND(('Global Precios'!$J23/('Global Precios'!$M23))*(1+'Global Precios'!$K23+0.1),10) -> 2060 | P23: 45261 | Q23: =LEN(D23) -> 49 | R23: 30 | T23: =IFERROR(VLOOKUP(D23,BUSCARV!$A$1:$C$5524,2,0),"") | V23: =IF(U23="",T23,T23/U23) | W23: =IF(V23="","", IFERROR((V23-J23)/J23,"")) | Y23: =IFERROR(VLOOKUP(A23,#REF!,3,0),0) -> 0 | Z23: Desactivado
A24: 23 | B24: 12396254 | C24: Producto | D24: EXCELLENT KITTEN Present: 7,5kg | E24: Excellent | F24: Alimentos | G24: Gato | H24: =IF(J24="","",J24/1.21) -> 43636.364 | I24: 0.065 | J24: 52800 | K24: 0.33 | L24: =IF('Global Precios'!J24*(1-I24)*(1+'Global Precios'!K24)>10000,MROUND('Global Precios'!J24*(1-I24)*(1+'Global Precios'!K24),1000),MROUND('Global Precios'!J24*(1-I24)*(1+'Global Precios'!K24),500)) -> 66000 | M24: 7.5 | N24: kg | O24: =+MROUND(('Global Precios'!$J24/('Global Precios'!$M24))*(1+'Global Precios'!$K24+0.1),10) -> 10070 | P24: 45839 | Q24: =LEN(D24) -> 31 | R24: 30 | T24: =IFERROR(VLOOKUP(D24,BUSCARV!$A$1:$C$5524,2,0),"") | V24: =IF(U24="",T24,T24/U24) | W24: =IF(V24="","", IFERROR((V24-J24)/J24,"")) | Y24: =IFERROR(VLOOKUP(A24,#REF!,3,0),0) -> 0 | Z24: Activo
A25: 24 | B25: 12396142 | C25: Producto | D25: EXCELLENT ADULT CAT Present: 7,5kg | E25: Excellent | F25: Alimentos | G25: Gato | H25: =IF(J25="","",J25/1.21) -> 39421.488 | I25: 0.065 | J25: 47700 | K25: 0.33 | L25: =IF('Global Precios'!J25*(1-I25)*(1+'Global Precios'!K25)>10000,MROUND('Global Precios'!J25*(1-I25)*(1+'Global Precios'!K25),1000),MROUND('Global Precios'!J25*(1-I25)*(1+'Global Precios'!K25),500)) -> 59000 | M25: 7.5 | N25: kg | O25: =+MROUND(('Global Precios'!$J25/('Global Precios'!$M25))*(1+'Global Precios'!$K25+0.1),10) -> 9090 | P25: 45839 | Q25: =LEN(D25) -> 34 | R25: 30 | T25: =IFERROR(VLOOKUP(D25,BUSCARV!$A$1:$C$5524,2,0),"") | V25: =IF(U25="",T25,T25/U25) | W25: =IF(V25="","", IFERROR((V25-J25)/J25,"")) | Y25: =IFERROR(VLOOKUP(A25,#REF!,3,0),0) -> 0 | Z25: Activo
A26: 25 | B26: 12376707 | C26: Producto | D26: TIDY CATS Piedra Convencional 2KG | E26: Tidy Cats | F26: Pet-shop | H26: 435 | I26: 0.08 | J26: 1209 | K26: 0.5 | L26: =IF('Global Precios'!J26*(1-I26)*(1+'Global Precios'!K26)>1000,MROUND('Global Precios'!J26*(1-I26)*(1+'Global Precios'!K26),100),MROUND('Global Precios'!J26*(1-I26)*(1+'Global Precios'!K26),10)) -> 1700 | M26: 2 | N26: kg | P26: 45323 | Q26: =LEN(D26) -> 33 | R26: 30 | T26: =IFERROR(VLOOKUP(D26,BUSCARV!$A$1:$C$5524,2,0),"") | V26: =IF(U26="",T26,T26/U26) | W26: =IF(V26="","", IFERROR((V26-J26)/J26,"")) | Y26: =IFERROR(VLOOKUP(A26,#REF!,3,0),0) -> 0 | Z26: Desactivado
A27: 26 | B27: 12434296 | C27: Producto | D27: FELIX Sensaciones de Pez x sobre de 0.85 g | E27: Excellent | F27: Alimentos | G27: Gato | H27: =IF(J27="","",J27/1.21) -> 684.29752 | I27: 0.05 | J27: 828 | K27: 0.4 | L27: =IF('Global Precios'!J27*(1-I27)*(1+'Global Precios'!K27)>1000,MROUND('Global Precios'!J27*(1-I27)*(1+'Global Precios'!K27),100),MROUND('Global Precios'!J27*(1-I27)*(1+'Global Precios'!K27),10)) -> 1100 | M27: 0.85 | N27: kg | O27: - | P27: 45323 | Q27: =LEN(D27) -> 42 | R27: 30 | T27: =IFERROR(VLOOKUP(D27,BUSCARV!$A$1:$C$5524,2,0),"") | V27: =IF(U27="",T27,T27/U27) | W27: =IF(V27="","", IFERROR((V27-J27)/J27,"")) | Y27: =IFERROR(VLOOKUP(A27,#REF!,3,0),0) -> 0 | Z27: Desactivado
A28: 27 | B28: YPATT17 | C28: Producto | D28: YENU ADULTO(todos los t.) Present: 17kg | E28: YENU | F28: Alimentos | G28: Perro | H28: =IF(J28="","",J28/1.21) -> 3016.5289 | J28: 3650 | K28: 0.34 | L28: =IF('Global Precios'!J28*(1-I28)*(1+'Global Precios'!K28)>1000,MROUND('Global Precios'!J28*(1-I28)*(1+'Global Precios'!K28),100),MROUND('Global Precios'!J28*(1-I28)*(1+'Global Precios'!K28),10)) -> 4900 | M28: 17 | N28: kg | O28: =+MROUND(('Global Precios'!$J28/('Global Precios'!$M28))*(1+'Global Precios'!$K28+0.1),10) -> 310 | P28: 44986 | Q28: =LEN(D28) -> 39 | R28: 0 | T28: =IFERROR(VLOOKUP(D28,BUSCARV!$A$1:$C$5524,2,0),"") | V28: =IF(U28="",T28,T28/U28) | W28: =IF(V28="","", IFERROR((V28-J28)/J28,"")) | Y28: =IFERROR(VLOOKUP(A28,#REF!,3,0),0) -> 0 | Z28: Desactivado
A29: 28 | B29: YPAMP3 | C29: Producto | D29: YENU ADULTO M.P Present: 3kg | E29: YENU | F29: Alimentos | G29: Perro | H29: =IF(J29="","",J29/1.21) -> 826.44628 | J29: 1000 | K29: 0.34 | L29: =IF('Global Precios'!J29*(1-I29)*(1+'Global Precios'!K29)>1000,MROUND('Global Precios'!J29*(1-I29)*(1+'Global Precios'!K29),100),MROUND('Global Precios'!J29*(1-I29)*(1+'Global Precios'!K29),10)) -> 1300 | M29: 3 | N29: kg | O29: - | P29: 44986 | Q29: =LEN(D29) -> 28 | R29: 0 | T29: =IFERROR(VLOOKUP(D29,BUSCARV!$A$1:$C$5524,2,0),"") | V29: =IF(U29="",T29,T29/U29) | W29: =IF(V29="","", IFERROR((V29-J29)/J29,"")) | Y29: =IFERROR(VLOOKUP(A29,#REF!,3,0),0) -> 0 | Z29: Desactivado
A30: 29 | B30: YPCTT10 | C30: Producto | D30: YENU CACHORROS(todos los t) Present: 10kg | E30: YENU | F30: Alimentos | G30: Perro | H30: =IF(J30="","",J30/1.21) -> 2190.0826 | J30: 2650 | K30: 0.34 | L30: =IF('Global Precios'!J30*(1-I30)*(1+'Global Precios'!K30)>1000,MROUND('Global Precios'!J30*(1-I30)*(1+'Global Precios'!K30),100),MROUND('Global Precios'!J30*(1-I30)*(1+'Global Precios'!K30),10)) -> 3600 | M30: 10 | N30: kg | O30: =+MROUND(('Global Precios'!$J30/('Global Precios'!$M30))*(1+'Global Precios'!$K30+0.1),10) -> 380 | P30: 44986 | Q30: =LEN(D30) -> 41 | R30: 0 | T30: =IFERROR(VLOOKUP(D30,BUSCARV!$A$1:$C$5524,2,0),"") | V30: =IF(U30="",T30,T30/U30) | W30: =IF(V30="","", IFERROR((V30-J30)/J30,"")) | Y30: =IFERROR(VLOOKUP(A30,#REF!,3,0),0) -> 0 | Z30: Desactivado
A31: 30 | B31: YPCMP3 | C31: Producto | D31: YENU CACHORROS M.P Present: 3kg | E31: YENU | F31: Alimentos | G31: Perro | H31: =IF(J31="","",J31/1.21) -> 867.7686 | J31: 1050 | K31: 0.34 | L31: =IF('Global Precios'!J31*(1-I31)*(1+'Global Precios'!K31)>1000,MROUND('Global Precios'!J31*(1-I31)*(1+'Global Precios'!K31),100),MROUND('Global Precios'!J31*(1-I31)*(1+'Global Precios'!K31),10)) -> 1400 | M31: 3 | N31: kg | O31: - | P31: 44986 | Q31: =LEN(D31) -> 31 | R31: 0 | T31: =IFERROR(VLOOKUP(D31,BUSCARV!$A$1:$C$5524,2,0),"") | V31: =IF(U31="",T31,T31/U31) | W31: =IF(V31="","", IFERROR((V31-J31)/J31,"")) | Y31: =IFERROR(VLOOKUP(A31,#REF!,3,0),0) -> 0 | Z31: Desactivado
A32: 31 | B32: YGA7 | C32: Producto | D32: YENU GATOS ADULTOS Present: 7,5kg | E32: YENU | F32: Alimentos | G32: Gato | H32: =IF(J32="","",J32/1.21) -> 2438.0165 | J32: 2950 | K32: 0.34 | L32: =IF('Global Precios'!J32*(1-I32)*(1+'Global Precios'!K32)>1000,MROUND('Global Precios'!J32*(1-I32)*(1+'Global Precios'!K32),100),MROUND('Global Precios'!J32*(1-I32)*(1+'Global Precios'!K32),10)) -> 4000 | M32: 7.5 | N32: kg | O32: =+MROUND(('Global Precios'!$J32/('Global Precios'!$M32))*(1+'Global Precios'!$K32+0.1),10) -> 570 | P32: 44986 | Q32: =LEN(D32) -> 33 | R32: 0 | T32: =IFERROR(VLOOKUP(D32,BUSCARV!$A$1:$C$5524,2,0),"") | V32: =IF(U32="",T32,T32/U32) | W32: =IF(V32="","", IFERROR((V32-J32)/J32,"")) | Y32: =IFERROR(VLOOKUP(A32,#REF!,3,0),0) -> 0 | Z32: Desactivado
A33: 32 | B33: YGC7 | C33: Producto | D33: YENU GATOS CACHORROS Present: 7,5kg | E33: YENU | F33: Alimentos | G33: Gato | H33: =IF(J33="","",J33/1.21) -> 2619.8347 | J33: 3170 | K33: 0.34 | L33: =IF('Global Precios'!J33*(1-I33)*(1+'Global Precios'!K33)>1000,MROUND('Global Precios'!J33*(1-I33)*(1+'Global Precios'!K33),100),MROUND('Global Precios'!J33*(1-I33)*(1+'Global Precios'!K33),10)) -> 4200 | M33: 7.5 | N33: kg | O33: =+MROUND(('Global Precios'!$J33/('Global Precios'!$M33))*(1+'Global Precios'!$K33+0.1),10) -> 610 | P33: 44986 | Q33: =LEN(D33) -> 35 | R33: 0 | T33: =IFERROR(VLOOKUP(D33,BUSCARV!$A$1:$C$5524,2,0),"") | V33: =IF(U33="",T33,T33/U33) | W33: =IF(V33="","", IFERROR((V33-J33)/J33,"")) | Y33: =IFERROR(VLOOKUP(A33,#REF!,3,0),0) -> 0 | Z33: Desactivado
A34: 33 | C34: Producto | D34: AGILITY ADULTO Present: 15kg | E34: Agility | F34: Alimentos | G34: Perro | H34: =IF(J34="","",J34/1.21) -> 7423.9669 | J34: 8983 | K34: 0.33 | L34: =IF('Global Precios'!J34*(1-I34)*(1+'Global Precios'!K34)>1000,MROUND('Global Precios'!J34*(1-I34)*(1+'Global Precios'!K34),100),MROUND('Global Precios'!J34*(1-I34)*(1+'Global Precios'!K34),10)) -> 11900 | M34: 15 | N34: kg | O34: - | P34: 45139 | Q34: =LEN(D34) -> 28 | R34: 30 | T34: =IFERROR(VLOOKUP(D34,BUSCARV!$A$1:$C$5524,2,0),"") | V34: =IF(U34="",T34,T34/U34) | W34: =IF(V34="","", IFERROR((V34-J34)/J34,"")) | Y34: =IFERROR(VLOOKUP(A34,#REF!,3,0),0) -> 0 | Z34: Desactivado
A35: 34 | C35: Producto | D35: AGILITY ADULTO Present: 20kg | E35: Agility | F35: Alimentos | G35: Perro | H35: =IF(J35="","",J35/1.21) -> 8347.1074 | J35: 10100 | K35: 0.33 | L35: =IF('Global Precios'!J35*(1-I35)*(1+'Global Precios'!K35)>1000,MROUND('Global Precios'!J35*(1-I35)*(1+'Global Precios'!K35),100),MROUND('Global Precios'!J35*(1-I35)*(1+'Global Precios'!K35),10)) -> 13400 | M35: 20 | N35: kg | O35: =+MROUND(('Global Precios'!$J35/('Global Precios'!$M35))*(1+'Global Precios'!$K35+0.1),10) -> 720 | P35: 45108 | Q35: =LEN(D35) -> 28 | R35: 30 | T35: =IFERROR(VLOOKUP(D35,BUSCARV!$A$1:$C$5524,2,0),"") | V35: =IF(U35="",T35,T35/U35) | W35: =IF(V35="","", IFERROR((V35-J35)/J35,"")) | Y35: =IFERROR(VLOOKUP(A35,#REF!,3,0),0) -> 0 | Z35: Desactivado
A36: 35 | C36: Producto | D36: AGILITY CACHORROS Present: 15kg | E36: Agility | F36: Alimentos | G36: Perro | H36: =IF(J36="","",J36/1.21) -> 7589.2562 | J36: 9183 | K36: 0.33 | L36: =IF('Global Precios'!J36*(1-I36)*(1+'Global Precios'!K36)>1000,MROUND('Global Precios'!J36*(1-I36)*(1+'Global Precios'!K36),100),MROUND('Global Precios'!J36*(1-I36)*(1+'Global Precios'!K36),10)) -> 12200 | M36: 15 | N36: kg | O36: - | P36: 45108 | Q36: =LEN(D36) -> 31 | R36: 30 | T36: =IFERROR(VLOOKUP(D36,BUSCARV!$A$1:$C$5524,2,0),"") | V36: =IF(U36="",T36,T36/U36) | W36: =IF(V36="","", IFERROR((V36-J36)/J36,"")) | Y36: =IFERROR(VLOOKUP(A36,#REF!,3,0),0) -> 0 | Z36: Desactivado
A37: 36 | C37: Producto | D37: AGILITY CACHORROS Present: 20kg | E37: Agility | F37: Alimentos | G37: Perro | H37: =IF(J37="","",J37/1.21) -> 9628.0992 | J37: 11650 | K37: 0.33 | L37: =IF('Global Precios'!J37*(1-I37)*(1+'Global Precios'!K37)>1000,MROUND('Global Precios'!J37*(1-I37)*(1+'Global Precios'!K37),100),MROUND('Global Precios'!J37*(1-I37)*(1+'Global Precios'!K37),10)) -> 15500 | M37: 20 | N37: kg | O37: =+MROUND(('Global Precios'!$J37/('Global Precios'!$M37))*(1+'Global Precios'!$K37+0.1),10) -> 830 | P37: 45108 | Q37: =LEN(D37) -> 31 | R37: 30 | T37: =IFERROR(VLOOKUP(D37,BUSCARV!$A$1:$C$5524,2,0),"") | V37: =IF(U37="",T37,T37/U37) | W37: =IF(V37="","", IFERROR((V37-J37)/J37,"")) | Y37: =IFERROR(VLOOKUP(A37,#REF!,3,0),0) -> 0 | Z37: Desactivado
A38: 37 | C38: Producto | D38: AGILITY CATS ADULTO Present: 10kg | E38: Agility | F38: Alimentos | G38: Gato | H38: =IF(J38="","",J38/1.21) -> 19504.132 | J38: 23600 | K38: 0.33 | L38: =IF('Global Precios'!J38*(1-I38)*(1+'Global Precios'!K38)>1000,MROUND('Global Precios'!J38*(1-I38)*(1+'Global Precios'!K38),100),MROUND('Global Precios'!J38*(1-I38)*(1+'Global Precios'!K38),10)) -> 31400 | M38: 10 | N38: kg | O38: =+MROUND(('Global Precios'!$J38/('Global Precios'!$M38))*(1+'Global Precios'!$K38+0.1),10) -> 3370 | P38: 45323 | Q38: =LEN(D38) -> 33 | R38: 30 | T38: =IFERROR(VLOOKUP(D38,BUSCARV!$A$1:$C$5524,2,0),"") | V38: =IF(U38="",T38,T38/U38) | W38: =IF(V38="","", IFERROR((V38-J38)/J38,"")) | Y38: =IFERROR(VLOOKUP(A38,#REF!,3,0),0) -> 0 | Z38: Desactivado
A39: 38 | C39: Producto | D39: AGILITY CATS KITTEN Present: 10kg | E39: Agility | F39: Alimentos | G39: Gato | H39: =IF(J39="","",J39/1.21) -> 8529.7521 | J39: 10321 | K39: 0.33 | L39: =IF('Global Precios'!J39*(1-I39)*(1+'Global Precios'!K39)>1000,MROUND('Global Precios'!J39*(1-I39)*(1+'Global Precios'!K39),100),MROUND('Global Precios'!J39*(1-I39)*(1+'Global Precios'!K39),10)) -> 13700 | M39: 10 | N39: kg | O39: =+MROUND(('Global Precios'!$J39/('Global Precios'!$M39))*(1+'Global Precios'!$K39+0.1),10) -> 1480 | P39: 45108 | Q39: =LEN(D39) -> 33 | R39: 30 | T39: =IFERROR(VLOOKUP(D39,BUSCARV!$A$1:$C$5524,2,0),"") | V39: =IF(U39="",T39,T39/U39) | W39: =IF(V39="","", IFERROR((V39-J39)/J39,"")) | Y39: =IFERROR(VLOOKUP(A39,#REF!,3,0),0) -> 0 | Z39: Desactivado
A40: 39 | C40: Producto | D40: DENTAL PLAX X 250 ML | E40: AFFORD | F40: Medicamentos | G40: VITAMINAS Y PROT. HEPATICOS,ETC | H40: =IF(J40="","",J40/1.21) -> 2644.6281 | J40: 3200 | K40: 0.8 | L40: =IF('Global Precios'!J40*(1-I40)*(1+'Global Precios'!K40)>10000,MROUND('Global Precios'!J40*(1-I40)*(1+'Global Precios'!K40),1000),MROUND('Global Precios'!J40*(1-I40)*(1+'Global Precios'!K40),500)) -> 6000 | M40: 250 | N40: ml | P40: 46082 | Q40: =LEN(D40) -> 20 | R40: 30 | T40: =IFERROR(VLOOKUP(D40,BUSCARV!$A$1:$C$5524,2,0),"") -> 2723 | V40: =IF(U40="",T40,T40/U40) -> 2723 | W40: =IF(V40="","", IFERROR((V40-J40)/J40,"")) -> -0.1490625 | Y40: =IFERROR(VLOOKUP(A40,#REF!,3,0),0) -> 0 | Z40: Activo
...

Sheet ADMGlobal
A1: =IF(E1="","", IF('Global Precios'!B2="",0,'Global Precios'!B2)) -> 0 | B1: =IF('Global Precios'!B2="","",'Global Precios'!B2) | C1: =IF('Global Precios'!A2="","",'Global Precios'!A2) -> 1 | E1: =IF('Global Precios'!D2="","",'Global Precios'!D2) -> Castración Gata | G1: =IFERROR(VLOOKUP(C1,'BuscarV Stock'!$A$2:$C$478,3,0),"AAA") -> 0 | H1: =IF(E1="","",0.21) -> 0.21 | I1: =IF('Global Precios'!H2="","",'Global Precios'!H2) -> 68163.636 | J1: =IF('Global Precios'!K2="","",'Global Precios'!K2) | K1: =IF('Global Precios'!Z2="Desactivado",0,IF('Global Precios'!L2="","",'Global Precios'!L2)) -> 82000 | R1: =IF('Global Precios'!F2="","",'Global Precios'!F2) -> Clinica | T1: =IF('Global Precios'!E2="","",'Global Precios'!E2) -> Arlekyn | V1: =IF(K1="","",0) -> 0 | AB1: =IF(K1="","",1) -> 1 | AC1: =IF(K1="","",1) -> 1 | AD1: =IF(K1="","",1) -> 1 | AE1: =AD1 -> 1
A2: =IF(E2="","", IF('Global Precios'!B3="",0,'Global Precios'!B3)) -> 0 | B2: =IF('Global Precios'!B3="","",'Global Precios'!B3) | C2: =IF('Global Precios'!A3="","",'Global Precios'!A3) -> 2 | E2: =IF('Global Precios'!D3="","",'Global Precios'!D3) -> Castración perra hasta 10 kg | G2: =IFERROR(VLOOKUP(C2,'BuscarV Stock'!$A$2:$C$478,3,0),"AAA") -> 0 | H2: =IF(E2="","",0.21) -> 0.21 | I2: =IF('Global Precios'!H3="","",'Global Precios'!H3) -> 83251.24 | J2: =IF('Global Precios'!K3="","",'Global Precios'!K3) | K2: =IF('Global Precios'!Z3="Desactivado",0,IF('Global Precios'!L3="","",'Global Precios'!L3)) -> 101000 | R2: =IF('Global Precios'!F3="","",'Global Precios'!F3) -> Clinica | T2: =IF('Global Precios'!E3="","",'Global Precios'!E3) -> Arlekyn | V2: =IF(K2="","",0) -> 0 | AB2: =IF(K2="","",1) -> 1 | AC2: =IF(K2="","",1) -> 1 | AD2: =IF(K2="","",1) -> 1 | AE2: =AD2 -> 1
A3: =IF(E3="","", IF('Global Precios'!B4="",0,'Global Precios'!B4)) -> 0 | B3: =IF('Global Precios'!B4="","",'Global Precios'!B4) | C3: =IF('Global Precios'!A4="","",'Global Precios'!A4) -> 3 | E3: =IF('Global Precios'!D4="","",'Global Precios'!D4) -> Castración perra hasta 20 kg | G3: =IFERROR(VLOOKUP(C3,'BuscarV Stock'!$A$2:$C$478,3,0),"AAA") -> 0 | H3: =IF(E3="","",0.21) -> 0.21 | I3: =IF('Global Precios'!H4="","",'Global Precios'!H4) -> 85819.835 | J3: =IF('Global Precios'!K4="","",'Global Precios'!K4) | K3: =IF('Global Precios'!Z4="Desactivado",0,IF('Global Precios'!L4="","",'Global Precios'!L4)) -> 104000 | R3: =IF('Global Precios'!F4="","",'Global Precios'!F4) -> Clinica | T3: =IF('Global Precios'!E4="","",'Global Precios'!E4) -> Arlekyn | V3: =IF(K3="","",0) -> 0 | AB3: =IF(K3="","",1) -> 1 | AC3: =IF(K3="","",1) -> 1 | AD3: =IF(K3="","",1) -> 1 | AE3: =AD3 -> 1
A4: =IF(E4="","", IF('Global Precios'!B5="",0,'Global Precios'!B5)) -> 0 | B4: =IF('Global Precios'!B5="","",'Global Precios'!B5) | C4: =IF('Global Precios'!A5="","",'Global Precios'!A5) -> 4 | E4: =IF('Global Precios'!D5="","",'Global Precios'!D5) -> Castración perra hasta 30 kg | G4: =IFERROR(VLOOKUP(C4,'BuscarV Stock'!$A$2:$C$478,3,0),"AAA") -> 0 | H4: =IF(E4="","",0.21) -> 0.21 | I4: =IF('Global Precios'!H5="","",'Global Precios'!H5) -> 90454.545 | J4: =IF('Global Precios'!K5="","",'Global Precios'!K5) | K4: =IF('Global Precios'!Z5="Desactivado",0,IF('Global Precios'!L5="","",'Global Precios'!L5)) -> 109000 | R4: =IF('Global Precios'!F5="","",'Global Precios'!F5) -> Clinica | T4: =IF('Global Precios'!E5="","",'Global Precios'!E5) -> Arlekyn | V4: =IF(K4="","",0) -> 0 | AB4: =IF(K4="","",1) -> 1 | AC4: =IF(K4="","",1) -> 1 | AD4: =IF(K4="","",1) -> 1 | AE4: =AD4 -> 1
A5: =IF(E5="","", IF('Global Precios'!B6="",0,'Global Precios'!B6)) -> 0 | B5: =IF('Global Precios'!B6="","",'Global Precios'!B6) | C5: =IF('Global Precios'!A6="","",'Global Precios'!A6) -> 5 | E5: =IF('Global Precios'!D6="","",'Global Precios'!D6) -> Castración perra hasta 40 kg | G5: =IFERROR(VLOOKUP(C5,'BuscarV Stock'!$A$2:$C$478,3,0),"AAA") -> 0 | H5: =IF(E5="","",0.21) -> 0.21 | I5: =IF('Global Precios'!H6="","",'Global Precios'!H6) -> 97890.083 | J5: =IF('Global Precios'!K6="","",'Global Precios'!K6) | K5: =IF('Global Precios'!Z6="Desactivado",0,IF('Global Precios'!L6="","",'Global Precios'!L6)) -> 118000 | R5: =IF('Global Precios'!F6="","",'Global Precios'!F6) -> Clinica | T5: =IF('Global Precios'!E6="","",'Global Precios'!E6) -> Arlekyn | V5: =IF(K5="","",0) -> 0 | AB5: =IF(K5="","",1) -> 1 | AC5: =IF(K5="","",1) -> 1 | AD5: =IF(K5="","",1) -> 1 | AE5: =AD5 -> 1
A6: =IF(E6="","", IF('Global Precios'!B7="",0,'Global Precios'!B7)) -> 0 | B6: =IF('Global Precios'!B7="","",'Global Precios'!B7) | C6: =IF('Global Precios'!A7="","",'Global Precios'!A7) -> 6 | E6: =IF('Global Precios'!D7="","",'Global Precios'!D7) -> Castración perra hasta 50 kg | G6: =IFERROR(VLOOKUP(C6,'BuscarV Stock'!$A$2:$C$478,3,0),"AAA") -> 0 | H6: =IF(E6="","",0.21) -> 0.21 | I6: =IF('Global Precios'!H7="","",'Global Precios'!H7) -> 105325.62 | J6: =IF('Global Precios'!K7="","",'Global Precios'!K7) | K6: =IF('Global Precios'!Z7="Desactivado",0,IF('Global Precios'!L7="","",'Global Precios'!L7)) -> 127000 | R6: =IF('Global Precios'!F7="","",'Global Precios'!F7) -> Clinica | T6: =IF('Global Precios'!E7="","",'Global Precios'!E7) -> Arlekyn | V6: =IF(K6="","",0) -> 0 | AB6: =IF(K6="","",1) -> 1 | AC6: =IF(K6="","",1) -> 1 | AD6: =IF(K6="","",1) -> 1 | AE6: =AD6 -> 1
A7: =IF(E7="","", IF('Global Precios'!B8="",0,'Global Precios'!B8)) -> 0 | B7: =IF('Global Precios'!B8="","",'Global Precios'!B8) | C7: =IF('Global Precios'!A8="","",'Global Precios'!A8) -> 7 | E7: =IF('Global Precios'!D8="","",'Global Precios'!D8) -> Castración perra hasta 60 kg | G7: =IFERROR(VLOOKUP(C7,'BuscarV Stock'!$A$2:$C$478,3,0),"AAA") -> 0 | H7: =IF(E7="","",0.21) -> 0.21 | I7: =IF('Global Precios'!H8="","",'Global Precios'!H8) -> 114000.83 | J7: =IF('Global Precios'!K8="","",'Global Precios'!K8) | K7: =IF('Global Precios'!Z8="Desactivado",0,IF('Global Precios'!L8="","",'Global Precios'!L8)) -> 138000 | R7: =IF('Global Precios'!F8="","",'Global Precios'!F8) -> Clinica | T7: =IF('Global Precios'!E8="","",'Global Precios'!E8) -> Arlekyn | V7: =IF(K7="","",0) -> 0 | AB7: =IF(K7="","",1) -> 1 | AC7: =IF(K7="","",1) -> 1 | AD7: =IF(K7="","",1) -> 1 | AE7: =AD7 -> 1
A8: =IF(E8="","", IF('Global Precios'!B9="",0,'Global Precios'!B9)) -> 0 | B8: =IF('Global Precios'!B9="","",'Global Precios'!B9) | C8: =IF('Global Precios'!A9="","",'Global Precios'!A9) -> 8 | E8: =IF('Global Precios'!D9="","",'Global Precios'!D9) -> Corte de colitas camadas hasta 3 cachorros | G8: =IFERROR(VLOOKUP(C8,'BuscarV Stock'!$A$2:$C$478,3,0),"AAA") -> 0 | H8: =IF(E8="","",0.21) -> 0.21 | I8: =IF('Global Precios'!H9="","",'Global Precios'!H9) -> 14871.074 | J8: =IF('Global Precios'!K9="","",'Global Precios'!K9) | K8: =IF('Global Precios'!Z9="Desactivado",0,IF('Global Precios'!L9="","",'Global Precios'!L9)) -> 0 | R8: =IF('Global Precios'!F9="","",'Global Precios'!F9) -> Clinica | T8: =IF('Global Precios'!E9="","",'Global Precios'!E9) -> Arlekyn | V8: =IF(K8="","",0) -> 0 | AB8: =IF(K8="","",1) -> 1 | AC8: =IF(K8="","",1) -> 1 | AD8: =IF(K8="","",1) -> 1 | AE8: =AD8 -> 1
A9: =IF(E9="","", IF('Global Precios'!B10="",0,'Global Precios'!B10)) -> 0 | B9: =IF('Global Precios'!B10="","",'Global Precios'!B10) | C9: =IF('Global Precios'!A10="","",'Global Precios'!A10) -> 9 | E9: =IF('Global Precios'!D10="","",'Global Precios'!D10) -> Corte de colitas camadas hasta 4 cachorros | G9: =IFERROR(VLOOKUP(C9,'BuscarV Stock'!$A$2:$C$478,3,0),"AAA") -> 0 | H9: =IF(E9="","",0.21) -> 0.21 | I9: =IF('Global Precios'!H10="","",'Global Precios'!H10) -> 12143.802 | J9: =IF('Global Precios'!K10="","",'Global Precios'!K10) | K9: =IF('Global Precios'!Z10="Desactivado",0,IF('Global Precios'!L10="","",'Global Precios'!L10)) -> 0 | R9: =IF('Global Precios'!F10="","",'Global Precios'!F10) -> Clinica | T9: =IF('Global Precios'!E10="","",'Global Precios'!E10) -> Arlekyn | V9: =IF(K9="","",0) -> 0 | AB9: =IF(K9="","",1) -> 1 | AC9: =IF(K9="","",1) -> 1 | AD9: =IF(K9="","",1) -> 1 | AE9: =AD9 -> 1
A10: =IF(E10="","", IF('Global Precios'!B11="",0,'Global Precios'!B11)) -> 0 | B10: =IF('Global Precios'!B11="","",'Global Precios'!B11) | C10: =IF('Global Precios'!A11="","",'Global Precios'!A11) -> 10 | E10: =IF('Global Precios'!D11="","",'Global Precios'!D11) -> Eutanasia hasta 10 kg | G10: =IFERROR(VLOOKUP(C10,'BuscarV Stock'!$A$2:$C$478,3,0),"AAA") -> 0 | H10: =IF(E10="","",0.21) -> 0.21 | I10: =IF('Global Precios'!H11="","",'Global Precios'!H11) -> 50544.628 | J10: =IF('Global Precios'!K11="","",'Global Precios'!K11) | K10: =IF('Global Precios'!Z11="Desactivado",0,IF('Global Precios'!L11="","",'Global Precios'!L11)) -> 61000 | R10: =IF('Global Precios'!F11="","",'Global Precios'!F11) -> Clinica | T10: =IF('Global Precios'!E11="","",'Global Precios'!E11) -> Arlekyn | V10: =IF(K10="","",0) -> 0 | AB10: =IF(K10="","",1) -> 1 | AC10: =IF(K10="","",1) -> 1 | AD10: =IF(K10="","",1) -> 1 | AE10: =AD10 -> 1
A11: =IF(E11="","", IF('Global Precios'!B12="",0,'Global Precios'!B12)) -> 0 | B11: =IF('Global Precios'!B12="","",'Global Precios'!B12) | C11: =IF('Global Precios'!A12="","",'Global Precios'!A12) -> 11 | E11: =IF('Global Precios'!D12="","",'Global Precios'!D12) -> Eutanasia hasta 20 kg | G11: =IFERROR(VLOOKUP(C11,'BuscarV Stock'!$A$2:$C$478,3,0),"AAA") -> 0 | H11: =IF(E11="","",0.21) -> 0.21 | I11: =IF('Global Precios'!H12="","",'Global Precios'!H12) -> 60022.314 | J11: =IF('Global Precios'!K12="","",'Global Precios'!K12) | K11: =IF('Global Precios'!Z12="Desactivado",0,IF('Global Precios'!L12="","",'Global Precios'!L12)) -> 73000 | R11: =IF('Global Precios'!F12="","",'Global Precios'!F12) -> Clinica | T11: =IF('Global Precios'!E12="","",'Global Precios'!E12) -> Arlekyn | V11: =IF(K11="","",0) -> 0 | AB11: =IF(K11="","",1) -> 1 | AC11: =IF(K11="","",1) -> 1 | AD11: =IF(K11="","",1) -> 1 | AE11: =AD11 -> 1
A12: =IF(E12="","", IF('Global Precios'!B13="",0,'Global Precios'!B13)) -> 0 | B12: =IF('Global Precios'!B13="","",'Global Precios'!B13) | C12: =IF('Global Precios'!A13="","",'Global Precios'!A13) -> 12 | E12: =IF('Global Precios'!D13="","",'Global Precios'!D13) -> Eutanasia hasta 30 kg | G12: =IFERROR(VLOOKUP(C12,'BuscarV Stock'!$A$2:$C$478,3,0),"AAA") -> 0 | H12: =IF(E12="","",0.21) -> 0.21 | I12: =IF('Global Precios'!H13="","",'Global Precios'!H13) -> 71605.785 | J12: =IF('Global Precios'!K13="","",'Global Precios'!K13) | K12: =IF('Global Precios'!Z13="Desactivado",0,IF('Global Precios'!L13="","",'Global Precios'!L13)) -> 87000 | R12: =IF('Global Precios'!F13="","",'Global Precios'!F13) -> Clinica | T12: =IF('Global Precios'!E13="","",'Global Precios'!E13) -> Arlekyn | V12: =IF(K12="","",0) -> 0 | AB12: =IF(K12="","",1) -> 1 | AC12: =IF(K12="","",1) -> 1 | AD12: =IF(K12="","",1) -> 1 | AE12: =AD12 -> 1
... A657: =IF(E657="","", IF('Global Precios'!B658="",0,'Global Precios'!B658)) -> 0 | B657: =IF('Global Precios'!B658="","",'Global Precios'!B658) | C657: =IF('Global Precios'!A658="","",'Global Precios'!A658) -> 689 | E657: =IF('Global Precios'!D658="","",'Global Precios'!D658) -> PONCHO TALLE 11 | G657: =IFERROR(VLOOKUP(C657,'BuscarV Stock'!$A$2:$C$478,3,0),"AAA") -> AAA | H657: =IF(E657="","",0.21) -> 0.21 | I657: =IF('Global Precios'!H658="","",'Global Precios'!H658) -> 3806.6116 | J657: =IF('Global Precios'!K658="","",'Global Precios'!K658) -> 0.8 | K657: =IF('Global Precios'!Z658="Desactivado",0,IF('Global Precios'!L658="","",'Global Precios'!L658)) -> 8300 | R657: =IF('Global Precios'!F658="","",'Global Precios'!F658) -> Pet-shop | T657: =IF('Global Precios'!E658="","",'Global Precios'!E658) | V657: =IF(K657="","",0) -> 0 | AB657: =IF(K657="","",1) -> 1 | AC657: =IF(K657="","",1) -> 1 | AD657: =IF(K657="","",1) -> 1 | AE657: =AD657 -> 1
A658: =IF(E658="","", IF('Global Precios'!B659="",0,'Global Precios'!B659)) -> 0 | B658: =IF('Global Precios'!B659="","",'Global Precios'!B659) | C658: =IF('Global Precios'!A659="","",'Global Precios'!A659) -> 692 | E658: =IF('Global Precios'!D659="","",'Global Precios'!D659) -> FLEE pulguicida y acaricida Aerosol | G658: =IFERROR(VLOOKUP(C658,'BuscarV Stock'!$A$2:$C$478,3,0),"AAA") -> AAA | H658: =IF(E658="","",0.21) -> 0.21 | I658: =IF('Global Precios'!H659="","",'Global Precios'!H659) -> 7851.2397 | J658: =IF('Global Precios'!K659="","",'Global Precios'!K659) | K658: =IF('Global Precios'!Z659="Desactivado",0,IF('Global Precios'!L659="","",'Global Precios'!L659)) -> 9500 | R658: =IF(#REF!="","",#REF!) -> #REF! | T658: =IF(#REF!="","",#REF!) -> #REF! | V658: =IF(K658="","",0) -> 0 | AB658: =IF(K658="","",1) -> 1 | AC658: =IF(K658="","",1) -> 1 | AD658: =IF(K658="","",1) -> 1 | AE658: =AD658 -> 1
A659: =IF(E659="","", IF('Global Precios'!B660="",0,'Global Precios'!B660)) -> 0 | B659: =IF('Global Precios'!B660="","",'Global Precios'!B660) | C659: =IF('Global Precios'!A660="","",'Global Precios'!A660) -> 693 | E659: =IF('Global Precios'!D660="","",'Global Precios'!D660) -> RESVITAL OMEGA ANTIOXIDANTE X 120 ML | G659: =IFERROR(VLOOKUP(C659,'BuscarV Stock'!$A$2:$C$478,3,0),"AAA") -> AAA | H659: =IF(E659="","",0.21) -> 0.21 | I659: =IF('Global Precios'!H660="","",'Global Precios'!H660) -> 12396.694 | J659: =IF('Global Precios'!K660="","",'Global Precios'!K660) | K659: =IF('Global Precios'!Z660="Desactivado",0,IF('Global Precios'!L660="","",'Global Precios'!L660)) -> 15000 | R659: =IF('Global Precios'!F659="","",'Global Precios'!F659) -> Medicamentos | T659: =IF('Global Precios'!E659="","",'Global Precios'!E659) -> Ruminal | V659: =IF(K659="","",0) -> 0 | AB659: =IF(K659="","",1) -> 1 | AC659: =IF(K659="","",1) -> 1 | AD659: =IF(K659="","",1) -> 1 | AE659: =AD659 -> 1
A660: =IF(E660="","", IF('Global Precios'!B661="",0,'Global Precios'!B661)) -> 0 | B660: =IF('Global Precios'!B661="","",'Global Precios'!B661) | C660: =IF('Global Precios'!A661="","",'Global Precios'!A661) -> 694 | E660: =IF('Global Precios'!D661="","",'Global Precios'!D661) -> PREGALBECH ORAL X 30 ML | G660: =IFERROR(VLOOKUP(C660,'BuscarV Stock'!$A$2:$C$478,3,0),"AAA") -> AAA | H660: =IF(E660="","",0.21) -> 0.21 | I660: =IF('Global Precios'!H661="","",'Global Precios'!H661) -> 14049.587 | J660: =IF('Global Precios'!K661="","",'Global Precios'!K661) | K660: =IF('Global Precios'!Z661="Desactivado",0,IF('Global Precios'!L661="","",'Global Precios'!L661)) -> 0 | R660: =IF('Global Precios'!F660="","",'Global Precios'!F660) -> Medicamentos | T660: =IF('Global Precios'!E660="","",'Global Precios'!E660) -> Bechlab | V660: =IF(K660="","",0) -> 0 | AB660: =IF(K660="","",1) -> 1 | AC660: =IF(K660="","",1) -> 1 | AD660: =IF(K660="","",1) -> 1 | AE660: =AD660 -> 1
A661: =IF(E661="","", IF('Global Precios'!B662="",0,'Global Precios'!B662)) -> 0 | B661: =IF('Global Precios'!B662="","",'Global Precios'!B662) | C661: =IF('Global Precios'!A662="","",'Global Precios'!A662) -> 695 | E661: =IF('Global Precios'!D662="","",'Global Precios'!D662) -> FLURAVET-C 20 kg | G661: =IFERROR(VLOOKUP(C661,'BuscarV Stock'!$A$2:$C$478,3,0),"AAA") -> AAA | H661: =IF(E661="","",0.21) -> 0.21 | I661: =IF('Global Precios'!H662="","",'Global Precios'!H662) -> 5206.6116 | J661: =IF('Global Precios'!K662="","",'Global Precios'!K662) | K661: =IF('Global Precios'!Z662="Desactivado",0,IF('Global Precios'!L662="","",'Global Precios'!L662)) -> 6300 | R661: =IF('Global Precios'!F661="","",'Global Precios'!F661) -> Medicamentos | T661: =IF('Global Precios'!E661="","",'Global Precios'!E661) -> Bechlab | V661: =IF(K661="","",0) -> 0 | AB661: =IF(K661="","",1) -> 1 | AC661: =IF(K661="","",1) -> 1 | AD661: =IF(K661="","",1) -> 1 | AE661: =AD661 -> 1
A662: =IF(E662="","", IF('Global Precios'!B663="",0,'Global Precios'!B663)) -> 0 | B662: =IF('Global Precios'!B663="","",'Global Precios'!B663) | C662: =IF('Global Precios'!A663="","",'Global Precios'!A663) -> 696 | E662: =IF('Global Precios'!D663="","",'Global Precios'!D663) -> FLURAVET-C 5 A 10 KG | G662: =IFERROR(VLOOKUP(C662,'BuscarV Stock'!$A$2:$C$478,3,0),"AAA") -> AAA | H662: =IF(E662="","",0.21) -> 0.21 | I662: =IF('Global Precios'!H663="","",'Global Precios'!H663) -> 9669.4215 | J662: =IF('Global Precios'!K663="","",'Global Precios'!K663) | K662: =IF('Global Precios'!Z663="Desactivado",0,IF('Global Precios'!L663="","",'Global Precios'!L663)) -> 11700 | R662: =IF('Global Precios'!F662="","",'Global Precios'!F662) -> Medicamentos | T662: =IF('Global Precios'!E662="","",'Global Precios'!E662) -> Alfa vet | V662: =IF(K662="","",0) -> 0 | AB662: =IF(K662="","",1) -> 1 | AC662: =IF(K662="","",1) -> 1 | AD662: =IF(K662="","",1) -> 1 | AE662: =AD662 -> 1
A663: =IF(E663="","", IF('Global Precios'!B664="",0,'Global Precios'!B664)) -> 0 | B663: =IF('Global Precios'!B664="","",'Global Precios'!B664) | C663: =IF('Global Precios'!A664="","",'Global Precios'!A664) -> 697 | E663: =IF('Global Precios'!D664="","",'Global Precios'!D664) -> TRILOBECH 10 MG X 10 COMP. | G663: =IFERROR(VLOOKUP(C663,'BuscarV Stock'!$A$2:$C$478,3,0),"AAA") -> AAA | H663: =IF(E663="","",0.21) -> 0.21 | I663: =IF('Global Precios'!H664="","",'Global Precios'!H664) -> 17355.372 | J663: =IF('Global Precios'!K664="","",'Global Precios'!K664) | K663: =IF('Global Precios'!Z664="Desactivado",0,IF('Global Precios'!L664="","",'Global Precios'!L664)) -> 21000 | R663: =IF('Global Precios'!F663="","",'Global Precios'!F663) -> Medicamentos | T663: =IF('Global Precios'!E663="","",'Global Precios'!E663) -> Alfa c | V663: =IF(K663="","",0) -> 0 | AB663: =IF(K663="","",1) -> 1 | AC663: =IF(K663="","",1) -> 1 | AD663: =IF(K663="","",1) -> 1 | AE663: =AD663 -> 1
A664: =IF(E664="","", IF('Global Precios'!B665="",0,'Global Precios'!B665)) -> 0 | B664: =IF('Global Precios'!B665="","",'Global Precios'!B665) | C664: =IF('Global Precios'!A665="","",'Global Precios'!A665) -> 698 | E664: =IF('Global Precios'!D665="","",'Global Precios'!D665) -> FLURAVET-C 4,6 A 10 kg | G664: =IFERROR(VLOOKUP(C664,'BuscarV Stock'!$A$2:$C$478,3,0),"AAA") -> AAA | H664: =IF(E664="","",0.21) -> 0.21 | I664: =IF('Global Precios'!H665="","",'Global Precios'!H665) -> 9917.3554 | J664: =IF('Global Precios'!K665="","",'Global Precios'!K665) | K664: =IF('Global Precios'!Z665="Desactivado",0,IF('Global Precios'!L665="","",'Global Precios'!L665)) -> 12000 | R664: =IF('Global Precios'!F664="","",'Global Precios'!F664) -> Medicamentos | T664: =IF('Global Precios'!E664="","",'Global Precios'!E664) -> Bechlab | V664: =IF(K664="","",0) -> 0 | AB664: =IF(K664="","",1) -> 1 | AC664: =IF(K664="","",1) -> 1 | AD664: =IF(K664="","",1) -> 1 | AE664: =AD664 -> 1
A665: =IF(E665="","", IF('Global Precios'!B666="",0,'Global Precios'!B666)) -> 0 | B665: =IF('Global Precios'!B666="","",'Global Precios'!B666) | C665: =IF('Global Precios'!A666="","",'Global Precios'!A666) -> 699 | E665: =IF('Global Precios'!D666="","",'Global Precios'!D666) -> FLURAVET-C 10 A 20 KG | G665: =IFERROR(VLOOKUP(C665,'BuscarV Stock'!$A$2:$C$478,3,0),"AAA") -> AAA | H665: =IF(E665="","",0.21) -> 0.21 | I665: =IF('Global Precios'!H666="","",'Global Precios'!H666) -> 12396.694 | J665: =IF('Global Precios'!K666="","",'Global Precios'!K666) | K665: =IF('Global Precios'!Z666="Desactivado",0,IF('Global Precios'!L666="","",'Global Precios'!L666)) -> 15000 | R665: =IF('Global Precios'!F665="","",'Global Precios'!F665) -> Medicamentos | T665: =IF('Global Precios'!E665="","",'Global Precios'!E665) -> Alfavet | V665: =IF(K665="","",0) -> 0 | AB665: =IF(K665="","",1) -> 1 | AC665: =IF(K665="","",1) -> 1 | AD665: =IF(K665="","",1) -> 1 | AE665: =AD665 -> 1
A666: =IF(E666="","", IF('Global Precios'!B667="",0,'Global Precios'!B667)) -> 0 | B666: =IF('Global Precios'!B667="","",'Global Precios'!B667) | C666: =IF('Global Precios'!A667="","",'Global Precios'!A667) -> 700 | E666: =IF('Global Precios'!D667="","",'Global Precios'!D667) -> FLURAVET-C 40 A 80 kg X 4 COMP. | G666: =IFERROR(VLOOKUP(C666,'BuscarV Stock'!$A$2:$C$478,3,0),"AAA") -> AAA | H666: =IF(E666="","",0.21) -> 0.21 | I666: =IF('Global Precios'!H667="","",'Global Precios'!H667) -> 5785.124 | J666: =IF('Global Precios'!K667="","",'Global Precios'!K667) | K666: =IF('Global Precios'!Z667="Desactivado",0,IF('Global Precios'!L667="","",'Global Precios'!L667)) -> 7000 | R666: =IF('Global Precios'!F666="","",'Global Precios'!F666) -> Medicamentos | T666: =IF('Global Precios'!E666="","",'Global Precios'!E666) -> Alfavet | V666: =IF(K666="","",0) -> 0 | AB666: =IF(K666="","",1) -> 1 | AC666: =IF(K666="","",1) -> 1 | AD666: =IF(K666="","",1) -> 1 | AE666: =AD666 -> 1
A667: =IF(E667="","", IF('Global Precios'!B668="",0,'Global Precios'!B668)) -> 0 | B667: =IF('Global Precios'!B668="","",'Global Precios'!B668) | C667: =IF('Global Precios'!A668="","",'Global Precios'!A668) -> 701 | E667: =IF('Global Precios'!D668="","",'Global Precios'!D668) -> PREGALBECH ORAL X 30 ML | G667: =IFERROR(VLOOKUP(C667,'BuscarV Stock'!$A$2:$C$478,3,0),"AAA") -> AAA | H667: =IF(E667="","",0.21) -> 0.21 | I667: =IF('Global Precios'!H668="","",'Global Precios'!H668) -> 14297.521 | J667: =IF('Global Precios'!K668="","",'Global Precios'!K668) | K667: =IF('Global Precios'!Z668="Desactivado",0,IF('Global Precios'!L668="","",'Global Precios'!L668)) -> 17300 | R667: =IF('Global Precios'!F667="","",'Global Precios'!F667) -> Medicamentos | T667: =IF('Global Precios'!E667="","",'Global Precios'!E667) -> Alfavet | V667: =IF(K667="","",0) -> 0 | AB667: =IF(K667="","",1) -> 1 | AC667: =IF(K667="","",1) -> 1 | AD667: =IF(K667="","",1) -> 1 | AE667: =AD667 -> 1
A668: =IF(E668="","", IF('Global Precios'!B669="",0,'Global Precios'!B669)) -> 0 | B668: =IF('Global Precios'!B669="","",'Global Precios'!B669) | C668: =IF('Global Precios'!A669="","",'Global Precios'!A669) -> 702 | E668: =IF('Global Precios'!D669="","",'Global Precios'!D669) -> GABALBECH ORAL X 30 ML | G668: =IFERROR(VLOOKUP(C668,'BuscarV Stock'!$A$2:$C$478,3,0),"AAA") -> AAA | H668: =IF(E668="","",0.21) -> 0.21 | I668: =IF('Global Precios'!H669="","",'Global Precios'!H669) -> 14297.521 | J668: =IF('Global Precios'!K669="","",'Global Precios'!K669) | K668: =IF('Global Precios'!Z669="Desactivado",0,IF('Global Precios'!L669="","",'Global Precios'!L669)) -> 17300 | R668: =IF('Global Precios'!F668="","",'Global Precios'!F668) -> Medicamentos | T668: =IF('Global Precios'!E668="","",'Global Precios'!E668) -> Bechlab | V668: =IF(K668="","",0) -> 0 | AB668: =IF(K668="","",1) -> 1 | AC668: =IF(K668="","",1) -> 1 | AD668: =IF(K668="","",1) -> 1 | AE668: =AD668 -> 1
A669: =IF(E669="","", IF('Global Precios'!B670="",0,'Global Precios'!B670)) -> 0 | B669: =IF('Global Precios'!B670="","",'Global Precios'!B670) | C669: =IF('Global Precios'!A670="","",'Global Precios'!A670) -> 703 | E669: =IF('Global Precios'!D670="","",'Global Precios'!D670) -> RENAL ADVANCED POLVO X 100 GRS | G669: =IFERROR(VLOOKUP(C669,'BuscarV Stock'!$A$2:$C$478,3,0),"AAA") -> AAA | H669: =IF(E669="","",0.21) -> 0.21 | I669: =IF('Global Precios'!H670="","",'Global Precios'!H670) -> 9423.9669 | J669: =IF('Global Precios'!K670="","",'Global Precios'!K670) | K669: =IF('Global Precios'!Z670="Desactivado",0,IF('Global Precios'!L670="","",'Global Precios'!L670)) -> 11400 | R669: =IF('Global Precios'!F669="","",'Global Precios'!F669) -> Medicamentos | T669: =IF('Global Precios'!E669="","",'Global Precios'!E669) -> Bechlab | V669: =IF(K669="","",0) -> 0 | AB669: =IF(K669="","",1) -> 1 | AC669: =IF(K669="","",1) -> 1 | AD669: =IF(K669="","",1) -> 1 | AE669: =AD669 -> 1
A670: =IF(E670="","", IF('Global Precios'!B671="",0,'Global Precios'!B671)) -> 0 | B670: =IF('Global Precios'!B671="","",'Global Precios'!B671) | C670: =IF('Global Precios'!A671="","",'Global Precios'!A671) -> 704 | E670: =IF('Global Precios'!D671="","",'Global Precios'!D671) -> NUTRIPET PALATABLE X 80 GRS | G670: =IFERROR(VLOOKUP(C670,'BuscarV Stock'!$A$2:$C$478,3,0),"AAA") -> AAA | H670: =IF(E670="","",0.21) -> 0.21 | I670: =IF('Global Precios'!H671="","",'Global Precios'!H671) -> 6446.281 | J670: =IF('Global Precios'!K671="","",'Global Precios'!K671) | K670: =IF('Global Precios'!Z671="Desactivado",0,IF('Global Precios'!L671="","",'Global Precios'!L671)) -> 7800 | R670: =IF('Global Precios'!F670="","",'Global Precios'!F670) -> Medicamentos | T670: =IF('Global Precios'!E670="","",'Global Precios'!E670) -> Bechlab | V670: =IF(K670="","",0) -> 0 | AB670: =IF(K670="","",1) -> 1 | AC670: =IF(K670="","",1) -> 1 | AD670: =IF(K670="","",1) -> 1 | AE670: =AD670 -> 1
... A677: =IF(E677="","", IF('Global Precios'!B678="",0,'Global Precios'!B678)) -> 0 | B677: =IF('Global Precios'!B678="","",'Global Precios'!B678) | C677: =IF('Global Precios'!A678="","",'Global Precios'!A678) -> 711 | E677: =IF('Global Precios'!D678="","",'Global Precios'!D678) -> JASPE GATO URINARY PREMIUM X 1 KG | G677: =IFERROR(VLOOKUP(C677,'BuscarV Stock'!$A$2:$C$478,3,0),"AAA") -> AAA | H677: =IF(E677="","",0.21) -> 0.21 | I677: =IF('Global Precios'!H678="","",'Global Precios'!H678) -> 3305.7851 | J677: =IF('Global Precios'!K678="","",'Global Precios'!K678) | K677: =IF('Global Precios'!Z678="Desactivado",0,IF('Global Precios'!L678="","",'Global Precios'!L678)) -> 4000 | R677: =IF('Global Precios'!F677="","",'Global Precios'!F677) -> Alimentos | T677: =IF('Global Precios'!E677="","",'Global Precios'!E677) -> EXCELLENT | V677: =IF(K677="","",0) -> 0 | AB677: =IF(K677="","",1) -> 1 | AC677: =IF(K677="","",1) -> 1 | AD677: =IF(K677="","",1) -> 1 | AE677: =AD677 -> 1
A678: =IF(E678="","", IF('Global Precios'!B686="",0,'Global Precios'!B686)) | B678: =IF('Global Precios'!B686="","",'Global Precios'!B686) | C678: =IF('Global Precios'!A686="","",'Global Precios'!A686) | E678: =IF('Global Precios'!D686="","",'Global Precios'!D686) | H678: =IF(E678="","",0.21) | I678: =IF('Global Precios'!H686="","",'Global Precios'!H686) | J678: =IF('Global Precios'!K686="","",'Global Precios'!K686) | K678: =IF('Global Precios'!Z686="Desactivado",0,IF('Global Precios'!L686="","",'Global Precios'!L686)) | R678: =IF('Global Precios'!F686="","",'Global Precios'!F686) | T678: =IF('Global Precios'!E686="","",'Global Precios'!E686) | V678: =IF(K678="","",0) | AB678: =IF(K678="","",1) | AC678: =IF(K678="","",1) | AD678: =IF(K678="","",1) | AE678: =AD678
A679: =IF(E679="","", IF('Global Precios'!B687="",0,'Global Precios'!B687)) | B679: =IF('Global Precios'!B687="","",'Global Precios'!B687) | C679: =IF('Global Precios'!A687="","",'Global Precios'!A687) | E679: =IF('Global Precios'!D687="","",'Global Precios'!D687) | H679: =IF(E679="","",0.21) | I679: =IF('Global Precios'!H687="","",'Global Precios'!H687) | J679: =IF('Global Precios'!K687="","",'Global Precios'!K687) | K679: =IF('Global Precios'!Z687="Desactivado",0,IF('Global Precios'!L687="","",'Global Precios'!L687)) | R679: =IF('Global Precios'!F687="","",'Global Precios'!F687) | T679: =IF('Global Precios'!E687="","",'Global Precios'!E687) | V679: =IF(K679="","",0) | AB679: =IF(K679="","",1) | AC679: =IF(K679="","",1) | AD679: =IF(K679="","",1) | AE679: =AD679
A680: =IF(E680="","", IF('Global Precios'!B688="",0,'Global Precios'!B688)) | B680: =IF('Global Precios'!B688="","",'Global Precios'!B688) | C680: =IF('Global Precios'!A688="","",'Global Precios'!A688) | E680: =IF('Global Precios'!D688="","",'Global Precios'!D688) | H680: =IF(E680="","",0.21) | I680: =IF('Global Precios'!H688="","",'Global Precios'!H688) | J680: =IF('Global Precios'!K688="","",'Global Precios'!K688) | K680: =IF('Global Precios'!Z688="Desactivado",0,IF('Global Precios'!L688="","",'Global Precios'!L688)) | R680: =IF('Global Precios'!F688="","",'Global Precios'!F688) | T680: =IF('Global Precios'!E688="","",'Global Precios'!E688) | V680: =IF(K680="","",0) | AB680: =IF(K680="","",1) | AC680: =IF(K680="","",1) | AD680: =IF(K680="","",1) | AE680: =AD680
A681: =IF(E681="","", IF('Global Precios'!B689="",0,'Global Precios'!B689)) | B681: =IF('Global Precios'!B689="","",'Global Precios'!B689) | C681: =IF('Global Precios'!A689="","",'Global Precios'!A689) | E681: =IF('Global Precios'!D689="","",'Global Precios'!D689) | H681: =IF(E681="","",0.21) | I681: =IF('Global Precios'!H689="","",'Global Precios'!H689) | J681: =IF('Global Precios'!K689="","",'Global Precios'!K689) | K681: =IF('Global Precios'!Z689="Desactivado",0,IF('Global Precios'!L689="","",'Global Precios'!L689)) | R681: =IF('Global Precios'!F689="","",'Global Precios'!F689) | T681: =IF('Global Precios'!E689="","",'Global Precios'!E689) | V681: =IF(K681="","",0) | AB681: =IF(K681="","",1) | AC681: =IF(K681="","",1) | AD681: =IF(K681="","",1) | AE681: =AD681
A682: =IF(E682="","", IF('Global Precios'!B690="",0,'Global Precios'!B690)) | B682: =IF('Global Precios'!B690="","",'Global Precios'!B690) | C682: =IF('Global Precios'!A690="","",'Global Precios'!A690) | E682: =IF('Global Precios'!D690="","",'Global Precios'!D690) | H682: =IF(E682="","",0.21) | I682: =IF('Global Precios'!H690="","",'Global Precios'!H690) | J682: =IF('Global Precios'!K690="","",'Global Precios'!K690) | K682: =IF('Global Precios'!Z690="Desactivado",0,IF('Global Precios'!L690="","",'Global Precios'!L690)) | R682: =IF('Global Precios'!F690="","",'Global Precios'!F690) | T682: =IF('Global Precios'!E690="","",'Global Precios'!E690) | V682: =IF(K682="","",0) | AB682: =IF(K682="","",1) | AC682: =IF(K682="","",1) | AD682: =IF(K682="","",1) | AE682: =AD682
A683: =IF(E683="","", IF('Global Precios'!B691="",0,'Global Precios'!B691)) | B683: =IF('Global Precios'!B691="","",'Global Precios'!B691) | C683: =IF('Global Precios'!A691="","",'Global Precios'!A691) | E683: =IF('Global Precios'!D691="","",'Global Precios'!D691) | H683: =IF(E683="","",0.21) | I683: =IF('Global Precios'!H691="","",'Global Precios'!H691) | J683: =IF('Global Precios'!K691="","",'Global Precios'!K691) | K683: =IF('Global Precios'!Z691="Desactivado",0,IF('Global Precios'!L691="","",'Global Precios'!L691)) | R683: =IF('Global Precios'!F691="","",'Global Precios'!F691) | T683: =IF('Global Precios'!E691="","",'Global Precios'!E691) | V683: =IF(K683="","",0) | AB683: =IF(K683="","",1) | AC683: =IF(K683="","",1) | AD683: =IF(K683="","",1) | AE683: =AD683
A684: =IF(E684="","", IF('Global Precios'!B692="",0,'Global Precios'!B692)) | B684: =IF('Global Precios'!B692="","",'Global Precios'!B692) | C684: =IF('Global Precios'!A692="","",'Global Precios'!A692) | E684: =IF('Global Precios'!D692="","",'Global Precios'!D692) | H684: =IF(E684="","",0.21) | I684: =IF('Global Precios'!H692="","",'Global Precios'!H692) | J684: =IF('Global Precios'!K692="","",'Global Precios'!K692) | K684: =IF('Global Precios'!Z692="Desactivado",0,IF('Global Precios'!L692="","",'Global Precios'!L692)) | R684: =IF('Global Precios'!F692="","",'Global Precios'!F692) | T684: =IF('Global Precios'!E692="","",'Global Precios'!E692) | V684: =IF(K684="","",0) | AB684: =IF(K684="","",1) | AC684: =IF(K684="","",1) | AD684: =IF(K684="","",1) | AE684: =AD684
A685: =IF(E685="","", IF('Global Precios'!B693="",0,'Global Precios'!B693)) | B685: =IF('Global Precios'!B693="","",'Global Precios'!B693) | C685: =IF('Global Precios'!A693="","",'Global Precios'!A693) | E685: =IF('Global Precios'!D693="","",'Global Precios'!D693) | H685: =IF(E685="","",0.21) | I685: =IF('Global Precios'!H693="","",'Global Precios'!H693) | J685: =IF('Global Precios'!K693="","",'Global Precios'!K693) | K685: =IF('Global Precios'!Z693="Desactivado",0,IF('Global Precios'!L693="","",'Global Precios'!L693)) | R685: =IF('Global Precios'!F693="","",'Global Precios'!F693) | T685: =IF('Global Precios'!E693="","",'Global Precios'!E693) | V685: =IF(K685="","",0) | AB685: =IF(K685="","",1) | AC685: =IF(K685="","",1) | AD685: =IF(K685="","",1) | AE685: =AD685
A686: =IF(E686="","", IF('Global Precios'!B694="",0,'Global Precios'!B694)) | B686: =IF('Global Precios'!B694="","",'Global Precios'!B694) | C686: =IF('Global Precios'!A694="","",'Global Precios'!A694) | E686: =IF('Global Precios'!D694="","",'Global Precios'!D694) | H686: =IF(E686="","",0.21) | I686: =IF('Global Precios'!H694="","",'Global Precios'!H694) | J686: =IF('Global Precios'!K694="","",'Global Precios'!K694) | K686: =IF('Global Precios'!Z694="Desactivado",0,IF('Global Precios'!L694="","",'Global Precios'!L694)) | R686: =IF('Global Precios'!F694="","",'Global Precios'!F694) | T686: =IF('Global Precios'!E694="","",'Global Precios'!E694) | V686: =IF(K686="","",0) | AB686: =IF(K686="","",1) | AC686: =IF(K686="","",1) | AD686: =IF(K686="","",1) | AE686: =AD686
A687: =IF(E687="","", IF('Global Precios'!B695="",0,'Global Precios'!B695)) | B687: =IF('Global Precios'!B695="","",'Global Precios'!B695) | C687: =IF('Global Precios'!A695="","",'Global Precios'!A695) | E687: =IF('Global Precios'!D695="","",'Global Precios'!D695) | H687: =IF(E687="","",0.21) | I687: =IF('Global Precios'!H695="","",'Global Precios'!H695) | J687: =IF('Global Precios'!K695="","",'Global Precios'!K695) | K687: =IF('Global Precios'!Z695="Desactivado",0,IF('Global Precios'!L695="","",'Global Precios'!L695)) | R687: =IF('Global Precios'!F695="","",'Global Precios'!F695) | T687: =IF('Global Precios'!E695="","",'Global Precios'!E695) | V687: =IF(K687="","",0) | AB687: =IF(K687="","",1) | AC687: =IF(K687="","",1) | AD687: =IF(K687="","",1) | AE687: =AD687
